<robot xmlns:xacro="http://www.ros.org/wiki/xacro" name="robot">

    <!-- Define materials -->
    <!-- ... (same as before) ... -->

    <link name="base_link"></link>

    <joint name="chassis_joint" type="fixed">
        <parent link="base_link"/>
        <child link="chassis"/>
        <origin xyz="-0.02 0 0"/>
    </joint>

    <link name="chassis">
        <visual>
            <origin xyz='0.125 0 0.04'/>
            <geometry>
                <box size="0.25 0.10 0.08"/>
            </geometry>
            <material name="white"/>
        </visual>
        <inertial>
            <origin xyz="0.125 0 0.04" rpy="0 0 0"/>
            <mass value="0.3"/>
            <inertia ixx="0.000104166667" ixy="0.0" ixz="0.0" iyy="0.0003125" iyz="0.0" izz="0.000260416667"/>
        </inertial>
    </link>

    <joint name="left_frontwheel_joint" type="revolute">
        <parent link="chassis"/>
        <child link="left_frontwheel"/>
        <origin xyz="0.23 0.06 0" rpy="0 0 0"/>
        <axis xyz="0 0 1"/>
        <limit effort="100" velocity="1.0" lower="-0.785" upper="0.785"/>
    </joint>

    <link name="left_frontwheel">
        <visual>
            <geometry>
                <cylinder radius="0.045" length="0.02"/>
            </geometry>
            <material name="black"/>
        </visual>
        <collision>
            <geometry>
                <cylinder radius="0.045" length="0.02"/>
            </geometry>
            <material name="black"/>
        </collision>
        <inertial>
            <origin xyz="0 0 0" rpy="0 0 0"/>
            <mass value="0.03"/>
            <inertia ixx="5.625e-06" ixy="0.0" ixz="0.0" iyy="1.25e-05" iyz="0.0" izz="1.25e-05"/>
        </inertial>
    </link>

    <joint name="right_frontwheel_joint" type="revolute">
        <parent link="chassis"/>
        <child link="right_frontwheel"/>
        <origin xyz="0.23 -0.06 0" rpy="0 0 0"/>
        <axis xyz="0 0 -1"/>
        <limit effort="100" velocity="1.0" lower="-0.785" upper="0.785"/>
    </joint>

    <link name="right_frontwheel">
        <visual>
            <geometry>
                <cylinder radius="0.045" length="0.02"/>
            </geometry>
            <material name="black"/>
        </visual>
        <collision>
            <geometry>
                <cylinder radius="0.045" length="0.02"/>
            </geometry>
            <material name="black"/>
        </collision>
        <inertial>
            <origin xyz="0 0 0" rpy="0 0 0"/>
            <mass value="0.03"/>
            <inertia ixx="5.625e-06" ixy="0.0" ixz="0.0" iyy="1.25e-05" iyz="0.0" izz="1.25e-05"/>
        </inertial>
    </link>

    <joint name="left_backwheel_joint" type="continuous">
        <parent link="base_link"/>
        <child link="left_backwheel"/>
        <origin xyz="0 0.06 0" rpy="-${pi/2} 0 0"/>
        <axis xyz="0 0 1"/>
    </joint>

    <link name="left_backwheel">
        <visual>
            <geometry>
                <cylinder radius="0.045" length="0.02"/>
            </geometry>
            <material name="black"/>
        </visual>
        <collision>
            <geometry>
                <cylinder radius="0.045" length="0.02"/>
            </geometry>
            <material name="black"/>
        </collision>
        <inertial>
            <origin xyz="0 0 0" rpy="0 0 0"/>
            <mass value="0.03"/>
            <inertia ixx="5.625e-06" ixy="0.0" ixz="0.0" iyy="1.25e-05" iyz="0.0" izz="1.25e-05"/>
        </inertial>
    </link>

    <joint name="right_backwheel_joint" type="continuous">
        <parent link="base_link"/>
        <child link="right_backwheel"/>
        <origin xyz="0 -0.06 0" rpy="${pi/2} 0 0"/>
        <axis xyz="0 0 -1"/>
    </joint>

    <link name="right_backwheel">
        <visual>
            <geometry>
                <cylinder radius="0.045" length="0.02"/>
            </geometry>
            <material name="black"/>
        </visual>
        <collision>
            <geometry>
                <cylinder radius="0.045" length="0.02"/>
            </geometry>
            <material name="black"/>
        </collision>
        <inertial>
            <origin xyz="0 0 0" rpy="0 0 0"/>
            <mass value="0.03"/>
            <inertia ixx="5.625e-06" ixy="0.0" ixz="0.0" iyy="1.25e-05" iyz="0.0" izz="1.25e-05"/>
        </inertial>
    </link>
</robot>
